<mujoco>
  <compiler autolimits="true"/>
  
  <!-- Setting to adjust camera/mouse sensitivity to match the car's scale. 
       Prevents the massive camera jump on mouse scroll since the initial track was huge. -->
  <statistic extent="3.0" center="0 0 0"/>

  <asset>
    <texture name="grid" type="2d" builtin="checker" width="512" height="512" rgb1=".1 .2 .3" rgb2=".2 .3 .4"/>
    <material name="grid" texture="grid" texrepeat="1 1" texuniform="true" reflectance=".2"/>
    <!-- Speed limit sign texture (path relative to this XML file's directory) -->
    <!-- <texture name="speed_limit_tex" type="2d" file="speed_limit.png"/> -->
    <texture name="speed_limit_tex" type="2d" file="stopsign.png"/>
    <material name="speed_limit_mat" texture="speed_limit_tex" texrepeat="1 1" texuniform="false"/>
  </asset>

  <default>
    <joint damping=".03" />
    <default class="wheel">
      <geom type="cylinder" size=".03 .01" rgba=".5 .5 1 1"/>
    </default>
    <default class="decor">
      <site type="box" rgba=".5 1 .5 1"/>
    </default>
    <!-- Steer knuckle joint: larger force range so position actuator can hold angle -->
    <default class="steer">
      <joint type="hinge" axis="0 0 1" range="-0.6 0.6" damping="0.1" actuatorfrcrange="-5 5"/>
    </default>
  </default>

  <worldbody>
    <!-- Wide grassy background -->
    <geom name="grass" type="plane" pos="15 0 -0.01" size="30 20 .01" rgba="0.15 0.4 0.15 1"/>
    
    <!-- 3-lane asphalt road (based on 15cm car width, 25cm lane width. Total width 75cm -> half-width 0.375) -->
    <geom name="road_asphalt" type="plane" pos="15 0 0" size="20 0.375 .01" rgba="0.2 0.2 0.2 1"/>
    
    <!-- White dashed lane lines (2cm thick, 1.5m dash length, 1.5m gap) -->
    <geom name="dash_-4.0_L" type="box" pos="-4.0 -0.125 0.002" size="0.125 0.01 0.001" rgba="1 1 1 1" contype="0" conaffinity="0"/>
    <geom name="dash_-4.0_R" type="box" pos="-4.0  0.125 0.002" size="0.125 0.01 0.001" rgba="1 1 1 1" contype="0" conaffinity="0"/>
    <geom name="dash_-3.5_L" type="box" pos="-3.5 -0.125 0.002" size="0.125 0.01 0.001" rgba="1 1 1 1" contype="0" conaffinity="0"/>
    <geom name="dash_-3.5_R" type="box" pos="-3.5  0.125 0.002" size="0.125 0.01 0.001" rgba="1 1 1 1" contype="0" conaffinity="0"/>
    <geom name="dash_-3.0_L" type="box" pos="-3.0 -0.125 0.002" size="0.125 0.01 0.001" rgba="1 1 1 1" contype="0" conaffinity="0"/>
    <geom name="dash_-3.0_R" type="box" pos="-3.0  0.125 0.002" size="0.125 0.01 0.001" rgba="1 1 1 1" contype="0" conaffinity="0"/>
    <geom name="dash_-2.5_L" type="box" pos="-2.5 -0.125 0.002" size="0.125 0.01 0.001" rgba="1 1 1 1" contype="0" conaffinity="0"/>
    <geom name="dash_-2.5_R" type="box" pos="-2.5  0.125 0.002" size="0.125 0.01 0.001" rgba="1 1 1 1" contype="0" conaffinity="0"/>
    <geom name="dash_-2.0_L" type="box" pos="-2.0 -0.125 0.002" size="0.125 0.01 0.001" rgba="1 1 1 1" contype="0" conaffinity="0"/>
    <geom name="dash_-2.0_R" type="box" pos="-2.0  0.125 0.002" size="0.125 0.01 0.001" rgba="1 1 1 1" contype="0" conaffinity="0"/>
    <geom name="dash_-1.5_L" type="box" pos="-1.5 -0.125 0.002" size="0.125 0.01 0.001" rgba="1 1 1 1" contype="0" conaffinity="0"/>
    <geom name="dash_-1.5_R" type="box" pos="-1.5  0.125 0.002" size="0.125 0.01 0.001" rgba="1 1 1 1" contype="0" conaffinity="0"/>
    <geom name="dash_-1.0_L" type="box" pos="-1.0 -0.125 0.002" size="0.125 0.01 0.001" rgba="1 1 1 1" contype="0" conaffinity="0"/>
    <geom name="dash_-1.0_R" type="box" pos="-1.0  0.125 0.002" size="0.125 0.01 0.001" rgba="1 1 1 1" contype="0" conaffinity="0"/>
    <geom name="dash_-0.5_L" type="box" pos="-0.5 -0.125 0.002" size="0.125 0.01 0.001" rgba="1 1 1 1" contype="0" conaffinity="0"/>
    <geom name="dash_-0.5_R" type="box" pos="-0.5  0.125 0.002" size="0.125 0.01 0.001" rgba="1 1 1 1" contype="0" conaffinity="0"/>
    <geom name="dash_0.0_L" type="box" pos="0.0 -0.125 0.002" size="0.125 0.01 0.001" rgba="1 1 1 1" contype="0" conaffinity="0"/>
    <geom name="dash_0.0_R" type="box" pos="0.0  0.125 0.002" size="0.125 0.01 0.001" rgba="1 1 1 1" contype="0" conaffinity="0"/>
    <geom name="dash_0.5_L" type="box" pos="0.5 -0.125 0.002" size="0.125 0.01 0.001" rgba="1 1 1 1" contype="0" conaffinity="0"/>
    <geom name="dash_0.5_R" type="box" pos="0.5  0.125 0.002" size="0.125 0.01 0.001" rgba="1 1 1 1" contype="0" conaffinity="0"/>
    <geom name="dash_1.0_L" type="box" pos="1.0 -0.125 0.002" size="0.125 0.01 0.001" rgba="1 1 1 1" contype="0" conaffinity="0"/>
    <geom name="dash_1.0_R" type="box" pos="1.0  0.125 0.002" size="0.125 0.01 0.001" rgba="1 1 1 1" contype="0" conaffinity="0"/>
    <geom name="dash_1.5_L" type="box" pos="1.5 -0.125 0.002" size="0.125 0.01 0.001" rgba="1 1 1 1" contype="0" conaffinity="0"/>
    <geom name="dash_1.5_R" type="box" pos="1.5  0.125 0.002" size="0.125 0.01 0.001" rgba="1 1 1 1" contype="0" conaffinity="0"/>
    <geom name="dash_2.0_L" type="box" pos="2.0 -0.125 0.002" size="0.125 0.01 0.001" rgba="1 1 1 1" contype="0" conaffinity="0"/>
    <geom name="dash_2.0_R" type="box" pos="2.0  0.125 0.002" size="0.125 0.01 0.001" rgba="1 1 1 1" contype="0" conaffinity="0"/>
    <geom name="dash_2.5_L" type="box" pos="2.5 -0.125 0.002" size="0.125 0.01 0.001" rgba="1 1 1 1" contype="0" conaffinity="0"/>
    <geom name="dash_2.5_R" type="box" pos="2.5  0.125 0.002" size="0.125 0.01 0.001" rgba="1 1 1 1" contype="0" conaffinity="0"/>
    <geom name="dash_3.0_L" type="box" pos="3.0 -0.125 0.002" size="0.125 0.01 0.001" rgba="1 1 1 1" contype="0" conaffinity="0"/>
    <geom name="dash_3.0_R" type="box" pos="3.0  0.125 0.002" size="0.125 0.01 0.001" rgba="1 1 1 1" contype="0" conaffinity="0"/>
    <geom name="dash_3.5_L" type="box" pos="3.5 -0.125 0.002" size="0.125 0.01 0.001" rgba="1 1 1 1" contype="0" conaffinity="0"/>
    <geom name="dash_3.5_R" type="box" pos="3.5  0.125 0.002" size="0.125 0.01 0.001" rgba="1 1 1 1" contype="0" conaffinity="0"/>
    <geom name="dash_4.0_L" type="box" pos="4.0 -0.125 0.002" size="0.125 0.01 0.001" rgba="1 1 1 1" contype="0" conaffinity="0"/>
    <geom name="dash_4.0_R" type="box" pos="4.0  0.125 0.002" size="0.125 0.01 0.001" rgba="1 1 1 1" contype="0" conaffinity="0"/>
    <geom name="dash_4.5_L" type="box" pos="4.5 -0.125 0.002" size="0.125 0.01 0.001" rgba="1 1 1 1" contype="0" conaffinity="0"/>
    <geom name="dash_4.5_R" type="box" pos="4.5  0.125 0.002" size="0.125 0.01 0.001" rgba="1 1 1 1" contype="0" conaffinity="0"/>
    <geom name="dash_5.0_L" type="box" pos="5.0 -0.125 0.002" size="0.125 0.01 0.001" rgba="1 1 1 1" contype="0" conaffinity="0"/>
    <geom name="dash_5.0_R" type="box" pos="5.0  0.125 0.002" size="0.125 0.01 0.001" rgba="1 1 1 1" contype="0" conaffinity="0"/>
    <geom name="dash_5.5_L" type="box" pos="5.5 -0.125 0.002" size="0.125 0.01 0.001" rgba="1 1 1 1" contype="0" conaffinity="0"/>
    <geom name="dash_5.5_R" type="box" pos="5.5  0.125 0.002" size="0.125 0.01 0.001" rgba="1 1 1 1" contype="0" conaffinity="0"/>
    <geom name="dash_6.0_L" type="box" pos="6.0 -0.125 0.002" size="0.125 0.01 0.001" rgba="1 1 1 1" contype="0" conaffinity="0"/>
    <geom name="dash_6.0_R" type="box" pos="6.0  0.125 0.002" size="0.125 0.01 0.001" rgba="1 1 1 1" contype="0" conaffinity="0"/>
    <geom name="dash_6.5_L" type="box" pos="6.5 -0.125 0.002" size="0.125 0.01 0.001" rgba="1 1 1 1" contype="0" conaffinity="0"/>
    <geom name="dash_6.5_R" type="box" pos="6.5  0.125 0.002" size="0.125 0.01 0.001" rgba="1 1 1 1" contype="0" conaffinity="0"/>
    <geom name="dash_7.0_L" type="box" pos="7.0 -0.125 0.002" size="0.125 0.01 0.001" rgba="1 1 1 1" contype="0" conaffinity="0"/>
    <geom name="dash_7.0_R" type="box" pos="7.0  0.125 0.002" size="0.125 0.01 0.001" rgba="1 1 1 1" contype="0" conaffinity="0"/>
    <geom name="dash_7.5_L" type="box" pos="7.5 -0.125 0.002" size="0.125 0.01 0.001" rgba="1 1 1 1" contype="0" conaffinity="0"/>
    <geom name="dash_7.5_R" type="box" pos="7.5  0.125 0.002" size="0.125 0.01 0.001" rgba="1 1 1 1" contype="0" conaffinity="0"/>
    <geom name="dash_8.0_L" type="box" pos="8.0 -0.125 0.002" size="0.125 0.01 0.001" rgba="1 1 1 1" contype="0" conaffinity="0"/>
    <geom name="dash_8.0_R" type="box" pos="8.0  0.125 0.002" size="0.125 0.01 0.001" rgba="1 1 1 1" contype="0" conaffinity="0"/>
    <geom name="dash_8.5_L" type="box" pos="8.5 -0.125 0.002" size="0.125 0.01 0.001" rgba="1 1 1 1" contype="0" conaffinity="0"/>
    <geom name="dash_8.5_R" type="box" pos="8.5  0.125 0.002" size="0.125 0.01 0.001" rgba="1 1 1 1" contype="0" conaffinity="0"/>
    <geom name="dash_9.0_L" type="box" pos="9.0 -0.125 0.002" size="0.125 0.01 0.001" rgba="1 1 1 1" contype="0" conaffinity="0"/>
    <geom name="dash_9.0_R" type="box" pos="9.0  0.125 0.002" size="0.125 0.01 0.001" rgba="1 1 1 1" contype="0" conaffinity="0"/>
    <geom name="dash_9.5_L" type="box" pos="9.5 -0.125 0.002" size="0.125 0.01 0.001" rgba="1 1 1 1" contype="0" conaffinity="0"/>
    <geom name="dash_9.5_R" type="box" pos="9.5  0.125 0.002" size="0.125 0.01 0.001" rgba="1 1 1 1" contype="0" conaffinity="0"/>
    <geom name="dash_10.0_L" type="box" pos="10.0 -0.125 0.002" size="0.125 0.01 0.001" rgba="1 1 1 1" contype="0" conaffinity="0"/>
    <geom name="dash_10.0_R" type="box" pos="10.0  0.125 0.002" size="0.125 0.01 0.001" rgba="1 1 1 1" contype="0" conaffinity="0"/>
    <geom name="dash_10.5_L" type="box" pos="10.5 -0.125 0.002" size="0.125 0.01 0.001" rgba="1 1 1 1" contype="0" conaffinity="0"/>
    <geom name="dash_10.5_R" type="box" pos="10.5  0.125 0.002" size="0.125 0.01 0.001" rgba="1 1 1 1" contype="0" conaffinity="0"/>
    <geom name="dash_11.0_L" type="box" pos="11.0 -0.125 0.002" size="0.125 0.01 0.001" rgba="1 1 1 1" contype="0" conaffinity="0"/>
    <geom name="dash_11.0_R" type="box" pos="11.0  0.125 0.002" size="0.125 0.01 0.001" rgba="1 1 1 1" contype="0" conaffinity="0"/>
    <geom name="dash_11.5_L" type="box" pos="11.5 -0.125 0.002" size="0.125 0.01 0.001" rgba="1 1 1 1" contype="0" conaffinity="0"/>
    <geom name="dash_11.5_R" type="box" pos="11.5  0.125 0.002" size="0.125 0.01 0.001" rgba="1 1 1 1" contype="0" conaffinity="0"/>
    <geom name="dash_12.0_L" type="box" pos="12.0 -0.125 0.002" size="0.125 0.01 0.001" rgba="1 1 1 1" contype="0" conaffinity="0"/>
    <geom name="dash_12.0_R" type="box" pos="12.0  0.125 0.002" size="0.125 0.01 0.001" rgba="1 1 1 1" contype="0" conaffinity="0"/>
    <geom name="dash_12.5_L" type="box" pos="12.5 -0.125 0.002" size="0.125 0.01 0.001" rgba="1 1 1 1" contype="0" conaffinity="0"/>
    <geom name="dash_12.5_R" type="box" pos="12.5  0.125 0.002" size="0.125 0.01 0.001" rgba="1 1 1 1" contype="0" conaffinity="0"/>
    <geom name="dash_13.0_L" type="box" pos="13.0 -0.125 0.002" size="0.125 0.01 0.001" rgba="1 1 1 1" contype="0" conaffinity="0"/>
    <geom name="dash_13.0_R" type="box" pos="13.0  0.125 0.002" size="0.125 0.01 0.001" rgba="1 1 1 1" contype="0" conaffinity="0"/>
    <geom name="dash_13.5_L" type="box" pos="13.5 -0.125 0.002" size="0.125 0.01 0.001" rgba="1 1 1 1" contype="0" conaffinity="0"/>
    <geom name="dash_13.5_R" type="box" pos="13.5  0.125 0.002" size="0.125 0.01 0.001" rgba="1 1 1 1" contype="0" conaffinity="0"/>
    <geom name="dash_14.0_L" type="box" pos="14.0 -0.125 0.002" size="0.125 0.01 0.001" rgba="1 1 1 1" contype="0" conaffinity="0"/>
    <geom name="dash_14.0_R" type="box" pos="14.0  0.125 0.002" size="0.125 0.01 0.001" rgba="1 1 1 1" contype="0" conaffinity="0"/>
    <geom name="dash_14.5_L" type="box" pos="14.5 -0.125 0.002" size="0.125 0.01 0.001" rgba="1 1 1 1" contype="0" conaffinity="0"/>
    <geom name="dash_14.5_R" type="box" pos="14.5  0.125 0.002" size="0.125 0.01 0.001" rgba="1 1 1 1" contype="0" conaffinity="0"/>
    <geom name="dash_15.0_L" type="box" pos="15.0 -0.125 0.002" size="0.125 0.01 0.001" rgba="1 1 1 1" contype="0" conaffinity="0"/>
    <geom name="dash_15.0_R" type="box" pos="15.0  0.125 0.002" size="0.125 0.01 0.001" rgba="1 1 1 1" contype="0" conaffinity="0"/>
    <geom name="dash_15.5_L" type="box" pos="15.5 -0.125 0.002" size="0.125 0.01 0.001" rgba="1 1 1 1" contype="0" conaffinity="0"/>
    <geom name="dash_15.5_R" type="box" pos="15.5  0.125 0.002" size="0.125 0.01 0.001" rgba="1 1 1 1" contype="0" conaffinity="0"/>
    <geom name="dash_16.0_L" type="box" pos="16.0 -0.125 0.002" size="0.125 0.01 0.001" rgba="1 1 1 1" contype="0" conaffinity="0"/>
    <geom name="dash_16.0_R" type="box" pos="16.0  0.125 0.002" size="0.125 0.01 0.001" rgba="1 1 1 1" contype="0" conaffinity="0"/>
    <geom name="dash_16.5_L" type="box" pos="16.5 -0.125 0.002" size="0.125 0.01 0.001" rgba="1 1 1 1" contype="0" conaffinity="0"/>
    <geom name="dash_16.5_R" type="box" pos="16.5  0.125 0.002" size="0.125 0.01 0.001" rgba="1 1 1 1" contype="0" conaffinity="0"/>
    <geom name="dash_17.0_L" type="box" pos="17.0 -0.125 0.002" size="0.125 0.01 0.001" rgba="1 1 1 1" contype="0" conaffinity="0"/>
    <geom name="dash_17.0_R" type="box" pos="17.0  0.125 0.002" size="0.125 0.01 0.001" rgba="1 1 1 1" contype="0" conaffinity="0"/>
    <geom name="dash_17.5_L" type="box" pos="17.5 -0.125 0.002" size="0.125 0.01 0.001" rgba="1 1 1 1" contype="0" conaffinity="0"/>
    <geom name="dash_17.5_R" type="box" pos="17.5  0.125 0.002" size="0.125 0.01 0.001" rgba="1 1 1 1" contype="0" conaffinity="0"/>
    <geom name="dash_18.0_L" type="box" pos="18.0 -0.125 0.002" size="0.125 0.01 0.001" rgba="1 1 1 1" contype="0" conaffinity="0"/>
    <geom name="dash_18.0_R" type="box" pos="18.0  0.125 0.002" size="0.125 0.01 0.001" rgba="1 1 1 1" contype="0" conaffinity="0"/>
    <geom name="dash_18.5_L" type="box" pos="18.5 -0.125 0.002" size="0.125 0.01 0.001" rgba="1 1 1 1" contype="0" conaffinity="0"/>
    <geom name="dash_18.5_R" type="box" pos="18.5  0.125 0.002" size="0.125 0.01 0.001" rgba="1 1 1 1" contype="0" conaffinity="0"/>
    <geom name="dash_19.0_L" type="box" pos="19.0 -0.125 0.002" size="0.125 0.01 0.001" rgba="1 1 1 1" contype="0" conaffinity="0"/>
    <geom name="dash_19.0_R" type="box" pos="19.0  0.125 0.002" size="0.125 0.01 0.001" rgba="1 1 1 1" contype="0" conaffinity="0"/>
    <geom name="dash_19.5_L" type="box" pos="19.5 -0.125 0.002" size="0.125 0.01 0.001" rgba="1 1 1 1" contype="0" conaffinity="0"/>
    <geom name="dash_19.5_R" type="box" pos="19.5  0.125 0.002" size="0.125 0.01 0.001" rgba="1 1 1 1" contype="0" conaffinity="0"/>
    <geom name="dash_20.0_L" type="box" pos="20.0 -0.125 0.002" size="0.125 0.01 0.001" rgba="1 1 1 1" contype="0" conaffinity="0"/>
    <geom name="dash_20.0_R" type="box" pos="20.0  0.125 0.002" size="0.125 0.01 0.001" rgba="1 1 1 1" contype="0" conaffinity="0"/>
    <geom name="dash_20.5_L" type="box" pos="20.5 -0.125 0.002" size="0.125 0.01 0.001" rgba="1 1 1 1" contype="0" conaffinity="0"/>
    <geom name="dash_20.5_R" type="box" pos="20.5  0.125 0.002" size="0.125 0.01 0.001" rgba="1 1 1 1" contype="0" conaffinity="0"/>
    <geom name="dash_21.0_L" type="box" pos="21.0 -0.125 0.002" size="0.125 0.01 0.001" rgba="1 1 1 1" contype="0" conaffinity="0"/>
    <geom name="dash_21.0_R" type="box" pos="21.0  0.125 0.002" size="0.125 0.01 0.001" rgba="1 1 1 1" contype="0" conaffinity="0"/>
    <geom name="dash_21.5_L" type="box" pos="21.5 -0.125 0.002" size="0.125 0.01 0.001" rgba="1 1 1 1" contype="0" conaffinity="0"/>
    <geom name="dash_21.5_R" type="box" pos="21.5  0.125 0.002" size="0.125 0.01 0.001" rgba="1 1 1 1" contype="0" conaffinity="0"/>
    <geom name="dash_22.0_L" type="box" pos="22.0 -0.125 0.002" size="0.125 0.01 0.001" rgba="1 1 1 1" contype="0" conaffinity="0"/>
    <geom name="dash_22.0_R" type="box" pos="22.0  0.125 0.002" size="0.125 0.01 0.001" rgba="1 1 1 1" contype="0" conaffinity="0"/>
    <geom name="dash_22.5_L" type="box" pos="22.5 -0.125 0.002" size="0.125 0.01 0.001" rgba="1 1 1 1" contype="0" conaffinity="0"/>
    <geom name="dash_22.5_R" type="box" pos="22.5  0.125 0.002" size="0.125 0.01 0.001" rgba="1 1 1 1" contype="0" conaffinity="0"/>
    <geom name="dash_23.0_L" type="box" pos="23.0 -0.125 0.002" size="0.125 0.01 0.001" rgba="1 1 1 1" contype="0" conaffinity="0"/>
    <geom name="dash_23.0_R" type="box" pos="23.0  0.125 0.002" size="0.125 0.01 0.001" rgba="1 1 1 1" contype="0" conaffinity="0"/>
    <geom name="dash_23.5_L" type="box" pos="23.5 -0.125 0.002" size="0.125 0.01 0.001" rgba="1 1 1 1" contype="0" conaffinity="0"/>
    <geom name="dash_23.5_R" type="box" pos="23.5  0.125 0.002" size="0.125 0.01 0.001" rgba="1 1 1 1" contype="0" conaffinity="0"/>
    <geom name="dash_24.0_L" type="box" pos="24.0 -0.125 0.002" size="0.125 0.01 0.001" rgba="1 1 1 1" contype="0" conaffinity="0"/>
    <geom name="dash_24.0_R" type="box" pos="24.0  0.125 0.002" size="0.125 0.01 0.001" rgba="1 1 1 1" contype="0" conaffinity="0"/>
    <geom name="dash_24.5_L" type="box" pos="24.5 -0.125 0.002" size="0.125 0.01 0.001" rgba="1 1 1 1" contype="0" conaffinity="0"/>
    <geom name="dash_24.5_R" type="box" pos="24.5  0.125 0.002" size="0.125 0.01 0.001" rgba="1 1 1 1" contype="0" conaffinity="0"/>
    <geom name="dash_25.0_L" type="box" pos="25.0 -0.125 0.002" size="0.125 0.01 0.001" rgba="1 1 1 1" contype="0" conaffinity="0"/>
    <geom name="dash_25.0_R" type="box" pos="25.0  0.125 0.002" size="0.125 0.01 0.001" rgba="1 1 1 1" contype="0" conaffinity="0"/>
    <geom name="dash_25.5_L" type="box" pos="25.5 -0.125 0.002" size="0.125 0.01 0.001" rgba="1 1 1 1" contype="0" conaffinity="0"/>
    <geom name="dash_25.5_R" type="box" pos="25.5  0.125 0.002" size="0.125 0.01 0.001" rgba="1 1 1 1" contype="0" conaffinity="0"/>
    <geom name="dash_26.0_L" type="box" pos="26.0 -0.125 0.002" size="0.125 0.01 0.001" rgba="1 1 1 1" contype="0" conaffinity="0"/>
    <geom name="dash_26.0_R" type="box" pos="26.0  0.125 0.002" size="0.125 0.01 0.001" rgba="1 1 1 1" contype="0" conaffinity="0"/>
    <geom name="dash_26.5_L" type="box" pos="26.5 -0.125 0.002" size="0.125 0.01 0.001" rgba="1 1 1 1" contype="0" conaffinity="0"/>
    <geom name="dash_26.5_R" type="box" pos="26.5  0.125 0.002" size="0.125 0.01 0.001" rgba="1 1 1 1" contype="0" conaffinity="0"/>
    <geom name="dash_27.0_L" type="box" pos="27.0 -0.125 0.002" size="0.125 0.01 0.001" rgba="1 1 1 1" contype="0" conaffinity="0"/>
    <geom name="dash_27.0_R" type="box" pos="27.0  0.125 0.002" size="0.125 0.01 0.001" rgba="1 1 1 1" contype="0" conaffinity="0"/>
    <geom name="dash_27.5_L" type="box" pos="27.5 -0.125 0.002" size="0.125 0.01 0.001" rgba="1 1 1 1" contype="0" conaffinity="0"/>
    <geom name="dash_27.5_R" type="box" pos="27.5  0.125 0.002" size="0.125 0.01 0.001" rgba="1 1 1 1" contype="0" conaffinity="0"/>
    <geom name="dash_28.0_L" type="box" pos="28.0 -0.125 0.002" size="0.125 0.01 0.001" rgba="1 1 1 1" contype="0" conaffinity="0"/>
    <geom name="dash_28.0_R" type="box" pos="28.0  0.125 0.002" size="0.125 0.01 0.001" rgba="1 1 1 1" contype="0" conaffinity="0"/>
    <geom name="dash_28.5_L" type="box" pos="28.5 -0.125 0.002" size="0.125 0.01 0.001" rgba="1 1 1 1" contype="0" conaffinity="0"/>
    <geom name="dash_28.5_R" type="box" pos="28.5  0.125 0.002" size="0.125 0.01 0.001" rgba="1 1 1 1" contype="0" conaffinity="0"/>
    <geom name="dash_29.0_L" type="box" pos="29.0 -0.125 0.002" size="0.125 0.01 0.001" rgba="1 1 1 1" contype="0" conaffinity="0"/>
    <geom name="dash_29.0_R" type="box" pos="29.0  0.125 0.002" size="0.125 0.01 0.001" rgba="1 1 1 1" contype="0" conaffinity="0"/>
    <geom name="dash_29.5_L" type="box" pos="29.5 -0.125 0.002" size="0.125 0.01 0.001" rgba="1 1 1 1" contype="0" conaffinity="0"/>
    <geom name="dash_29.5_R" type="box" pos="29.5  0.125 0.002" size="0.125 0.01 0.001" rgba="1 1 1 1" contype="0" conaffinity="0"/>
    <geom name="dash_30.0_L" type="box" pos="30.0 -0.125 0.002" size="0.125 0.01 0.001" rgba="1 1 1 1" contype="0" conaffinity="0"/>
    <geom name="dash_30.0_R" type="box" pos="30.0  0.125 0.002" size="0.125 0.01 0.001" rgba="1 1 1 1" contype="0" conaffinity="0"/>
    <geom name="dash_30.5_L" type="box" pos="30.5 -0.125 0.002" size="0.125 0.01 0.001" rgba="1 1 1 1" contype="0" conaffinity="0"/>
    <geom name="dash_30.5_R" type="box" pos="30.5  0.125 0.002" size="0.125 0.01 0.001" rgba="1 1 1 1" contype="0" conaffinity="0"/>
    <geom name="dash_31.0_L" type="box" pos="31.0 -0.125 0.002" size="0.125 0.01 0.001" rgba="1 1 1 1" contype="0" conaffinity="0"/>
    <geom name="dash_31.0_R" type="box" pos="31.0  0.125 0.002" size="0.125 0.01 0.001" rgba="1 1 1 1" contype="0" conaffinity="0"/>
    <geom name="dash_31.5_L" type="box" pos="31.5 -0.125 0.002" size="0.125 0.01 0.001" rgba="1 1 1 1" contype="0" conaffinity="0"/>
    <geom name="dash_31.5_R" type="box" pos="31.5  0.125 0.002" size="0.125 0.01 0.001" rgba="1 1 1 1" contype="0" conaffinity="0"/>
    <geom name="dash_32.0_L" type="box" pos="32.0 -0.125 0.002" size="0.125 0.01 0.001" rgba="1 1 1 1" contype="0" conaffinity="0"/>
    <geom name="dash_32.0_R" type="box" pos="32.0  0.125 0.002" size="0.125 0.01 0.001" rgba="1 1 1 1" contype="0" conaffinity="0"/>
    <geom name="dash_32.5_L" type="box" pos="32.5 -0.125 0.002" size="0.125 0.01 0.001" rgba="1 1 1 1" contype="0" conaffinity="0"/>
    <geom name="dash_32.5_R" type="box" pos="32.5  0.125 0.002" size="0.125 0.01 0.001" rgba="1 1 1 1" contype="0" conaffinity="0"/>
    <geom name="dash_33.0_L" type="box" pos="33.0 -0.125 0.002" size="0.125 0.01 0.001" rgba="1 1 1 1" contype="0" conaffinity="0"/>
    <geom name="dash_33.0_R" type="box" pos="33.0  0.125 0.002" size="0.125 0.01 0.001" rgba="1 1 1 1" contype="0" conaffinity="0"/>
    <geom name="dash_33.5_L" type="box" pos="33.5 -0.125 0.002" size="0.125 0.01 0.001" rgba="1 1 1 1" contype="0" conaffinity="0"/>
    <geom name="dash_33.5_R" type="box" pos="33.5  0.125 0.002" size="0.125 0.01 0.001" rgba="1 1 1 1" contype="0" conaffinity="0"/>
    <geom name="dash_34.0_L" type="box" pos="34.0 -0.125 0.002" size="0.125 0.01 0.001" rgba="1 1 1 1" contype="0" conaffinity="0"/>
    <geom name="dash_34.0_R" type="box" pos="34.0  0.125 0.002" size="0.125 0.01 0.001" rgba="1 1 1 1" contype="0" conaffinity="0"/>
    <geom name="dash_34.5_L" type="box" pos="34.5 -0.125 0.002" size="0.125 0.01 0.001" rgba="1 1 1 1" contype="0" conaffinity="0"/>
    <geom name="dash_34.5_R" type="box" pos="34.5  0.125 0.002" size="0.125 0.01 0.001" rgba="1 1 1 1" contype="0" conaffinity="0"/>
    <geom name="dash_35.0_L" type="box" pos="35.0 -0.125 0.002" size="0.125 0.01 0.001" rgba="1 1 1 1" contype="0" conaffinity="0"/>
    <geom name="dash_35.0_R" type="box" pos="35.0  0.125 0.002" size="0.125 0.01 0.001" rgba="1 1 1 1" contype="0" conaffinity="0"/>
    
    <!-- Yellow edge lines (matched to road width) -->
    <geom name="edge_line_L" type="box" pos="15 -0.37 0.002" size="20 0.01 0.001" rgba="1 0.8 0 1" contype="0" conaffinity="0"/>
    <geom name="edge_line_R" type="box" pos="15  0.37 0.002" size="20 0.01 0.001" rgba="1 0.8 0 1" contype="0" conaffinity="0"/>
    
    <!-- Goal line and visual arch at 23.0m (scaled proportionally to the narrowed width) -->
    <site name="goal_site" pos="23.0 0 0.005" size="0.2 0.375 0.005" type="box" rgba="0 1 0 0.8"/>
    <geom name="goal_pole_L" type="cylinder" pos="23.0 -0.375 0.4" size="0.02 0.4" rgba="1 0.2 0.2 1"/>
    <geom name="goal_pole_R" type="cylinder" pos="23.0  0.375 0.4" size="0.02 0.4" rgba="1 0.2 0.2 1"/>
    <geom name="goal_top" type="box" pos="23.0 0 0.82" size="0.02 0.375 0.02" rgba="1 0.2 0.2 1"/>

    <!-- === Speed Limit Sign (x=21.5m, 1.5m before goal, right side of road y=0.62) ===
         The sign faces the approaching driver (visible on ±X faces of the thin box). -->
    <!-- Metal post -->
    <geom name="sign_post" type="cylinder"
          pos="21.5 0.62 0.40" size="0.022 0.40"
          rgba="0.65 0.65 0.68 1" contype="0" conaffinity="0"/>
    <!-- Sign board: thin in X (0.025m), wide in Y (0.36m total), tall in Z (0.48m total)
         texture mapped on the large ±X faces via YZ coordinates -->
    <geom name="sign_board" type="box"
          pos="21.5 0.62 0.73" size="0.24 0.18 0.025"
          euler="0 -90 0"
          material="speed_limit_mat"
          contype="0" conaffinity="0"/>

    <!-- Floating "GOAL" text (bright yellow neon sign effect, hovering above the goal arch) -->
    <!-- "G" (Y center: 0.3) -->
    <geom name="G_top" type="box" pos="23.0 0.3 1.025" size="0.005 0.05 0.01" rgba="1 0.9 0 1" contype="0" conaffinity="0"/>
    <geom name="G_bot" type="box" pos="23.0 0.3 0.875" size="0.005 0.05 0.01" rgba="1 0.9 0 1" contype="0" conaffinity="0"/>
    <geom name="G_left" type="box" pos="23.0 0.35 0.95" size="0.005 0.01 0.075" rgba="1 0.9 0 1" contype="0" conaffinity="0"/>
    <geom name="G_right_bot" type="box" pos="23.0 0.25 0.9125" size="0.005 0.01 0.0375" rgba="1 0.9 0 1" contype="0" conaffinity="0"/>
    <geom name="G_mid" type="box" pos="23.0 0.275 0.95" size="0.005 0.025 0.01" rgba="1 0.9 0 1" contype="0" conaffinity="0"/>
    <geom name="G_nub" type="box" pos="23.0 0.25 1.0125" size="0.005 0.01 0.0125" rgba="1 0.9 0 1" contype="0" conaffinity="0"/>

    <!-- "O" (Y center: 0.1) -->
    <geom name="O_top" type="box" pos="23.0 0.1 1.025" size="0.005 0.05 0.01" rgba="1 0.9 0 1" contype="0" conaffinity="0"/>
    <geom name="O_bot" type="box" pos="23.0 0.1 0.875" size="0.005 0.05 0.01" rgba="1 0.9 0 1" contype="0" conaffinity="0"/>
    <geom name="O_left" type="box" pos="23.0 0.15 0.95" size="0.005 0.01 0.075" rgba="1 0.9 0 1" contype="0" conaffinity="0"/>
    <geom name="O_right" type="box" pos="23.0 0.05 0.95" size="0.005 0.01 0.075" rgba="1 0.9 0 1" contype="0" conaffinity="0"/>

    <!-- "A" (Y center: -0.1) -->
    <geom name="A_top" type="box" pos="23.0 -0.1 1.025" size="0.005 0.05 0.01" rgba="1 0.9 0 1" contype="0" conaffinity="0"/>
    <geom name="A_mid" type="box" pos="23.0 -0.1 0.95" size="0.005 0.05 0.01" rgba="1 0.9 0 1" contype="0" conaffinity="0"/>
    <geom name="A_left" type="box" pos="23.0 -0.05 0.95" size="0.005 0.01 0.075" rgba="1 0.9 0 1" contype="0" conaffinity="0"/>
    <geom name="A_right" type="box" pos="23.0 -0.15 0.95" size="0.005 0.01 0.075" rgba="1 0.9 0 1" contype="0" conaffinity="0"/>

    <!-- "L" (Y center: -0.3) -->
    <geom name="L_left" type="box" pos="23.0 -0.25 0.95" size="0.005 0.01 0.075" rgba="1 0.9 0 1" contype="0" conaffinity="0"/>
    <geom name="L_bot" type="box" pos="23.0 -0.3 0.875" size="0.005 0.05 0.01" rgba="1 0.9 0 1" contype="0" conaffinity="0"/>
    <body name="car" pos="0 0 .03">
      <freejoint/>
      <light name="top light" pos="0 0 2" mode="trackcom" diffuse=".4 .4 .4"/>
      <!-- Box chassis: main body slab (taller floor) -->
      <geom name="chassis_body" type="box" pos="0.005 0 0.012" size="0.077 0.040 0.020" rgba=".45 .45 .5 1"/>
      <!-- Tall cabin enclosure -->
      <geom name="chassis_cabin" type="box" pos="0.00 0 0.068" size="0.045 0.033 0.034" rgba=".38 .38 .43 1"/>
      <!-- Front axle strut (non-collideable visual) -->
      <geom name="axle_front" type="box" pos="0.08 0 0" size="0.010 0.058 0.007" rgba=".3 .3 .35 1" contype="0" conaffinity="0"/>
      <!-- Rear axle strut (non-collideable visual) -->
      <geom name="axle_rear" type="box" pos="-0.07 0 0" size="0.010 0.058 0.007" rgba=".3 .3 .35 1" contype="0" conaffinity="0"/>
      <!-- Steering column (fixed to chassis, does not rotate) -->
      <geom name="steering_column" type="cylinder" pos="0.046 0 0.040"
            size="0.003 0.016" zaxis="-0.70 0 0.70"
            rgba=".18 .18 .18 1" contype="0" conaffinity="0"/>
      <!-- Steering wheel body: rotates around column axis when turning.
           zaxis="-0.707 0 0.707" → body local-Z aligns with the column direction.
           All child geoms are in the local XY-plane (a circle of radius 0.018). -->
      <body name="steer_wheel_body" pos="0.028 0 0.058" zaxis="-0.707 0 0.707">
        <inertial pos="0 0 0" mass="0.005" diaginertia="1e-6 1e-6 1e-6"/>
        <!-- Joint: hinge around local Z = steering-column axis; high damping to resist drift -->
        <joint name="steer_visual" type="hinge" axis="0 0 1" damping="500" actuatorfrcrange="-0 0"/>
        <!-- Hub -->
        <geom name="sw_hub" type="sphere" pos="0 0 0"
              size="0.006" rgba=".25 .25 .25 1" contype="0" conaffinity="0"/>
        <!-- Outer rim: 12 capsule arc segments (30° each, R=0.018m)
             Midpoint of segment k is at angle (15+30k)°.
             pos = R*(cos θ, sin θ, 0),  zaxis = (-sin θ, cos θ, 0)
             Arc chord half-length = R*sin(15°) ≈ 0.0047 -->
        <geom name="sw_r0"  type="capsule" pos=" 0.01739  0.00466 0" size="0.0018 0.0047" zaxis="-0.259  0.966 0" rgba=".15 .15 .15 1" contype="0" conaffinity="0"/>
        <geom name="sw_r1"  type="capsule" pos=" 0.01273  0.01273 0" size="0.0018 0.0047" zaxis="-0.707  0.707 0" rgba=".15 .15 .15 1" contype="0" conaffinity="0"/>
        <geom name="sw_r2"  type="capsule" pos=" 0.00466  0.01739 0" size="0.0018 0.0047" zaxis="-0.966  0.259 0" rgba=".15 .15 .15 1" contype="0" conaffinity="0"/>
        <geom name="sw_r3"  type="capsule" pos="-0.00466  0.01739 0" size="0.0018 0.0047" zaxis="-0.966 -0.259 0" rgba=".15 .15 .15 1" contype="0" conaffinity="0"/>
        <geom name="sw_r4"  type="capsule" pos="-0.01273  0.01273 0" size="0.0018 0.0047" zaxis="-0.707 -0.707 0" rgba=".15 .15 .15 1" contype="0" conaffinity="0"/>
        <geom name="sw_r5"  type="capsule" pos="-0.01739  0.00466 0" size="0.0018 0.0047" zaxis="-0.259 -0.966 0" rgba=".15 .15 .15 1" contype="0" conaffinity="0"/>
        <geom name="sw_r6"  type="capsule" pos="-0.01739 -0.00466 0" size="0.0018 0.0047" zaxis=" 0.259 -0.966 0" rgba=".15 .15 .15 1" contype="0" conaffinity="0"/>
        <geom name="sw_r7"  type="capsule" pos="-0.01273 -0.01273 0" size="0.0018 0.0047" zaxis=" 0.707 -0.707 0" rgba=".15 .15 .15 1" contype="0" conaffinity="0"/>
        <geom name="sw_r8"  type="capsule" pos="-0.00466 -0.01739 0" size="0.0018 0.0047" zaxis=" 0.966 -0.259 0" rgba=".15 .15 .15 1" contype="0" conaffinity="0"/>
        <geom name="sw_r9"  type="capsule" pos=" 0.00466 -0.01739 0" size="0.0018 0.0047" zaxis=" 0.966  0.259 0" rgba=".15 .15 .15 1" contype="0" conaffinity="0"/>
        <geom name="sw_r10" type="capsule" pos=" 0.01273 -0.01273 0" size="0.0018 0.0047" zaxis=" 0.707  0.707 0" rgba=".15 .15 .15 1" contype="0" conaffinity="0"/>
        <geom name="sw_r11" type="capsule" pos=" 0.01739 -0.00466 0" size="0.0018 0.0047" zaxis=" 0.259  0.966 0" rgba=".15 .15 .15 1" contype="0" conaffinity="0"/>
        <!-- 3 spokes: screen-vertical bottom (local -X = 180°), upper-right (60°), upper-left (300°)
             In camera view: local +X → screen up, local +Y → screen left
             Symmetric 120° spacing with bottom spoke exactly vertical on screen -->
        <geom name="sw_sp0" type="capsule" pos="-0.00900  0.00000 0" size="0.0020 0.0090" zaxis="-1.000  0.000 0" rgba=".25 .25 .25 1" contype="0" conaffinity="0"/>
        <geom name="sw_sp1" type="capsule" pos=" 0.00450 -0.00779 0" size="0.0020 0.0090" zaxis=" 0.500 -0.866 0" rgba=".25 .25 .25 1" contype="0" conaffinity="0"/>
        <geom name="sw_sp2" type="capsule" pos=" 0.00450  0.00779 0" size="0.0020 0.0090" zaxis=" 0.500  0.866 0" rgba=".25 .25 .25 1" contype="0" conaffinity="0"/>
      </body>
      <!-- Driver first-person camera: looking forward ~20° downward to see steering wheel -->
      <!-- xyaxes: cam_x=(0,-1,0)=car_right, cam_y=(0.342,0,0.940)=up-tilted-fwd → looks in +X and -Z -->
      <camera name="driver_cam" pos="0.005 0 0.092" xyaxes="0 -1 0 0.342 0 0.940" fovy="75"/>
      <!-- Front-left: outer body = steer (yaw), inner body = roll (spin) -->
      <body name="front_left_steer" pos=".08 .06 0">
        <inertial pos="0 0 0" mass="0.001" diaginertia="1e-6 1e-6 1e-6"/>
        <joint name="steer_left" class="steer"/>
        <body name="front_left_wheel" zaxis="0 1 0">
          <joint name="roll_front_left" type="hinge" axis="0 0 1" damping="0.002"/>
          <geom class="wheel" priority="1"/>
          <site class="decor" size=".006 .025 .012"/>
          <site class="decor" size=".025 .006 .012"/>
        </body>
      </body>
      <!-- Front-right: outer body = steer (yaw), inner body = roll (spin) -->
      <body name="front_right_steer" pos=".08 -.06 0">
        <inertial pos="0 0 0" mass="0.001" diaginertia="1e-6 1e-6 1e-6"/>
        <joint name="steer_right" class="steer"/>
        <body name="front_right_wheel" zaxis="0 1 0">
          <joint name="roll_front_right" type="hinge" axis="0 0 1" damping="0.002"/>
          <geom class="wheel" priority="1"/>
          <site class="decor" size=".006 .025 .012"/>
          <site class="decor" size=".025 .006 .012"/>
        </body>
      </body>
      <light name="front light" pos=".1 0 .02" dir="2 0 -1" diffuse="1 1 1"/>
      <body name="left wheel" pos="-.07 .06 0" zaxis="0 1 0">
        <joint name="left"/>
        <geom class="wheel"/>
        <site class="decor" size=".006 .025 .012"/>
        <site class="decor" size=".025 .006 .012"/>
      </body>
      <body name="right wheel" pos="-.07 -.06 0" zaxis="0 1 0">
        <joint name="right"/>
        <geom class="wheel"/>
        <site class="decor" size=".006 .025 .012"/>
        <site class="decor" size=".025 .006 .012"/>
      </body>
    </body>
  </worldbody>

  <tendon>
    <!-- Rear wheel drive: both rear wheels spin together -->
    <fixed name="forward">
      <joint joint="left" coef=".5"/>
      <joint joint="right" coef=".5"/>
    </fixed>
    <!-- Front steering: turn knuckle controls both front wheels -->
    <fixed name="turn">
      <joint joint="steer_left" coef=".5"/>
      <joint joint="steer_right" coef=".5"/>
    </fixed>
  </tendon>

  <actuator>
    <motor name="forward" tendon="forward" ctrlrange="-1 1"/>
    <!-- position actuator: ctrl sets target angle (rad) for front wheel steering -->
    <position name="turn" tendon="turn" kp="10" ctrlrange="-0.5 0.5"/>
  </actuator>

  <sensor>
    <jointactuatorfrc name="right" joint="right"/>
    <jointactuatorfrc name="left" joint="left"/>
  </sensor>
</mujoco>
